[toc]

# 异常介绍

## 异常分类

程序中难免出现错误，总共可分为两种。

1.逻辑错误

2.语法错误

对于刚接触编程的人来说，这两个错误都会经常去犯，但是随着经验慢慢的积累，语法错误的情况会越来越少反而逻辑错误的情况会越来越多（因为工程量巨大）。

不论多么老道的程序员都不可避免出现这两种错误。

## 异常信息

异常其实就是程序运行时发生错误的信号，我们写代码的过程中不可避免也最害怕的就是出现异常，然而当程序抛出异常时实际上会分为三部分，即三大信息。

![image-20200624135540455](Python/f2529d08bdbacc1c3686005146d513c1.png)

## 常见异常

在Python中一切皆对象，异常本身也是由一个类生成的，NameError其实本身就是一个异常类，其他诸如此类的异常类还有很多，如下表所示。

| 异常类          | 描述                                                       |
| --------------- | ---------------------------------------------------------- |
| AttributeError  | 属性错误，被查找属性不存在                                 |
| IOError         | IO错误，文件无法打开                                       |
| ImportError     | 导包错误，导入模块或包时给定了错误的路径或导入了没有的功能 |
| IndentaionError | 缩进错误，代码没有正确对齐                                 |
| KeyError        | 键错误，获取字典中不存在的键                               |
| NameError       | 标识符错误，试图使用一个未被赋值的标识符                   |
| SyntaxError     | 语法错误，代码写错了                                       |
| TypeError       | 类型错误，传入对象的类型和预期不符                         |
| ValueError      | 值错误，传入一个调用者不期望的值，即使值的类型是正确的     |
| AssertionError  | 断言异常                                                   |

# 异常处理

我们可以来用某些方法进行异常捕捉，当出现异常时我们希望代码以另一种逻辑运行，使得我们的程序更加健壮，这个就叫做异常处理。

异常处理是非常重要的，本身也并不复杂，千万不可马虎大意，但是切记不可滥用异常处理，这会使得你的代码可读性变差。

## if else处理异常

if和else本身就具有处理异常的功能，他们更多的是在我们能预测到可能出现异常的范围内进行规避异常，对于我们不能预测的异常来说就显得不是那么的好用。

如下所示，我们仅期待用户输入数字，如果是输入其他内容则会被其他逻辑所处理：

```python
while 1:
    choice = input("Please enter a digital string:")
    if choice.isdigit():
        print("success!!")
        break
    else:
        print("You input not is a digital string!!")

```

## try/except

try和except是最常用的一种异常处理方式。

- try：代表要检测可能出现异常的代码块
- except：当特定异常出现后的处理情况

执行流程如下：

- try中检测的代码块
  - 如果有异常
  - 执行except代码块
  - 执行正常逻辑
  - 执行完毕
- try中检测的代码块
  - 如果无异常
  - 执行完try中代码快
  - 执行正常逻辑
  - 执行完毕

![image-20210612182100998](Python/e9f86a419644e63a94e40b58ade95494.png)

示例如下，try中未抛出异常：

```python
lst = [i for i in range(3)]

try:
    print("run try")
    print(lst[2])
except IndexError as e:
    print("run except")

print("normal code")

# run try
# 2
# normal code

```

示例如下，try中抛出异常：

```python
lst = [i for i in range(3)]

try:
    print("run try")
    print(lst[3])
except IndexError as e:
    print("run except")

print("normal code")

# run try
# run except
# normal code

```

### 多段except捕捉多异常

使用1个try和多个except来捕捉多种可能出现的异常：

```python
lst = [i for i in range(3)]
dic = dict.fromkeys((chr(i) for i in range(65, 68)), None)

try:
    print(lst[2])
    print(dic["D"])
except IndexError as e:
    print("index error %s " % e)
except KeyError as e:
    print("key error %s" % e)

print("normal code")

# 2
# key error 'D'
# normal code

```

### 元组捕获多异常

使用多段except处理多异常会显得麻烦，可以使用except (error1, error2)来处理多个异常。

但是多个异常只有1个处理结果，故处理逻辑可能会写的比较麻烦：

```python
lst = [i for i in range(3)]
dic = dict.fromkeys((chr(i) for i in range(65, 68)), None)

try:
    print(lst[2])
    print(dic["D"])
except (IndexError, KeyError) as e:
    if isinstance(e, IndexError):
        print("index error %s" % e)
    elif isinstance(e, KeyError):
        print("key error %s" % e)

print("normal code")

# 2
# key error 'D'
# normal code

```

### except捕获万能异常

使用except Exception来捕捉所有可能出现的异常，Exception是所有异常的基类。

Exception类的父类则是BaseException类，而BaseException的父类则是object类

```python
lst = [i for i in range(3)]
dic = dict.fromkeys((chr(i) for i in range(65, 68)), None)

try:
    print(lst[2])
    print(dic["D"])
except Exception as e:
    if isinstance(e, IndexError):
        print("index error %s" % e)
    elif isinstance(e, KeyError):
        print("key error %s" % e)

print("normal code")

# 2
# key error 'D'
# normal code

```

## try/except/esle

else代表没有异常发生的情况下执行的代码，如下图所示：

![image-20210612183837371](Python/6a813453b84258e5b314a1a7ec5a144e.png)

```python
lst = [i for i in range(3)]
dic = dict.fromkeys((chr(i) for i in range(65, 68)), None)

try:
    print(lst[2])
    print(dic["A"])
except Exception as e:
    if isinstance(e, IndexError):
        print("index error %s" % e)
    elif isinstance(e, KeyError):
        print("key error %s" % e)
else:
    print("don't have throw an exception")

print("normal code")

# 2
# None
# don't have throw an exception
# normal code

```

## try/except/else/finally

finally代表不论抛异常与否都会执行，因此常被用作关闭系统资源的操作。

如下图所示：

![image-20210612185902177](Python/25926a132d4adf7840772d7da9fa5459.png)

```python
lst = [i for i in range(3)]
dic = dict.fromkeys((chr(i) for i in range(65, 68)), None)

try:
    print(lst[2])
    print(dic["A"])
except Exception as e:
    if isinstance(e, IndexError):
        print("index error %s" % e)
    elif isinstance(e, KeyError):
        print("key error %s" % e)
else:
    print("don't have throw an exception")
finally:
    print("last run this")

print("normal code")

# 2
# None
# don't have throw an exception
# last run this
# normal code

```

# 主动抛出异常

在某些时候我们可能需要主动的去阻止程序的运行，主动的抛出一个异常。

以防止逻辑越错越远。

## raise

raise可以主动的抛出一个异常，如下所示：

```python
lst = [i for i in range(3)]
l = input("please input %s length >>>" % lst)

if not l.isdigit():
    raise TypeError("you must input number")
    
if int(l) != len(lst):
    raise ValueError("your length input error, he length is not %s" % l)
    
if int(l) == len(lst):
    print("success!!")

```

## assert

断言内部会进行if判断，如果判断结果为False则抛出AssertionError异常，如果为True就不抛出AssertionError异常。

如下所示：

```python
lst = [i for i in range(3)]
l = input("please input %s length >>>" % lst)

assert l.isdigit(), "you must input number"

assert int(l) == len(lst), "your length input error, he length is not %s" % l

print("success!!")

"""
please input [0, 1, 2] length >>>a
Traceback (most recent call last):
  File "D:/openstack_v/source/LearnPython/test1.py", line 4, in <module>
    assert l.isdigit(), "you must input number"
AssertionError: you must input number
"""
```

# 自定义异常

前面已经说过一切皆对象，异常也来自一个对象，所以我们可以自定义一个异常，只需要继承BaseException类即可。

如下示例，内置异常没有InputTypeError，我们来自己定义一个：

```python
class InputTypeError(BaseException):
    pass

lst = [i for i in range(3)]
l = input("please input %s length >>>" % lst)

if not l.isdigit():
    raise InputTypeError("you must input number")
    
if int(l) != len(lst):
    raise ValueError("your length input error, he length is not %s" % l)
    
if int(l) == len(lst):
    print("success!!")

```

